Workbook

Sheet PSS
A1: App | B1: Productos | C1: Cuenta contable | D1: Saldo Aplicativo Sin filtros | E1: Saldo Aplicativo con Filtros Agrupaciones aplicados | F1: Saldos Diario 16 Abril Operativo | G1: Cuadre Con Filtros | H1: Cuadre Sin Filtros | I1: Filtros aplicados | J1: Detalle cuenta contable
A2: $IM | B2: Cuentas Corrientes | C2: 14010204000106 | D2: 248.15 | E2: 248.15 | F2: 248.15 | G2: =F2-E2 -> 0 | H2: =F2-D2 -> 0 | J2: =VLOOKUP(C2,'[1]GLOCUENTAS (1)'!$B:$C,2,FALSE) -> SOBREGIRO CTAS CTE S/F PJ MES106 1ND
C3: 14010301000101 | D3: 1.82 | E3: 1.82 | F3: 1.82 | G3: =F3-E3 -> 0 | H3: =F3-D3 -> 0 | J3: =VLOOKUP(C3,'[1]GLOCUENTAS (1)'!$B:$C,2,FALSE) -> AVANCES EN CTA CTE CONTRATADOS PN 1ND
C4: 14010801000102 | D4: 0 | E4: 0 | F4: 0 | G4: =F4-E4 -> 0 | H4: =F4-D4 -> 0 | J4: =VLOOKUP(C4,'[1]GLOCUENTAS (1)'!$B:$C,2,FALSE) -> IM AVANCE CTA CTE PJ S/F CIVA 1ND
C5: 14010804000102 | D5: 0 | E5: 0 | F5: 0 | G5: =F5-E5 -> 0 | H5: =F5-D5 -> 0 | J5: =VLOOKUP(C5,'[1]GLOCUENTAS (1)'!$B:$C,2,FALSE) -> IM SOBREGIRO CTA CTE PJ S/F CIVA 1ND
C6: 14010999010901 | D6: 0 | E6: 0 | F6: 0 | G6: =F6-E6 -> 0 | H6: =F6-D6 -> 0 | J6: =VLOOKUP(C6,'[1]GLOCUENTAS (1)'!$B:$C,2,FALSE) -> BANCO FINANCIERO DEL PERU 1ND
C7: 14011001000102 | D7: 52837788 | E7: 52837788 | F7: 52837788 | G7: =F7-E7 -> 0 | H7: =F7-D7 -> 0 | J7: =VLOOKUP(C7,'[1]GLOCUENTAS (1)'!$B:$C,2,FALSE) -> IM AVANCE CTA CTE PJ S/F CCOR 1ND
C8: 14011004000102 | D8: 1364645.7 | E8: 1364645.7 | F8: 1364645.7 | G8: =F8-E8 -> 0 | H8: =F8-D8 -> 0 | J8: =VLOOKUP(C8,'[1]GLOCUENTAS (1)'!$B:$C,2,FALSE) -> IM SOBREGIRO CTA CTE PJ S/F CCOR 1ND
C9: 14011004000103 | D9: 0 | E9: 0 | F9: 0 | G9: =F9-E9 -> 0 | H9: =F9-D9 -> 0 | J9: =VLOOKUP(C9,'[1]GLOCUENTAS (1)'!$B:$C,2,FALSE) -> IM SOBRG CTA CTE S/F PJ CCOR 1ND
C10: 14011101000102 | D10: 178927.89 | E10: 178927.89 | F10: 178927.89 | G10: =F10-E10 -> 0 | H10: =F10-D10 -> 0 | J10: =VLOOKUP(C10,'[1]GLOCUENTAS (1)'!$B:$C,2,FALSE) -> IM AVANCE CTA CTE PJ S/F CGEM 1ND
C11: 14011104000102 | D11: 46065.87 | E11: 46065.87 | F11: 46065.87 | G11: =F11-E11 -> 0 | H11: =F11-D11 -> 0 | J11: =VLOOKUP(C11,'[1]GLOCUENTAS (1)'!$B:$C,2,FALSE) -> IM SOBREGIRO CTA CTE PJ S/F CGEM 1ND
C12: 14011104000103 | D12: 105.14 | E12: 105.14 | F12: 105.14 | G12: =F12-E12 -> 0 | H12: =F12-D12 -> 0 | J12: =VLOOKUP(C12,'[1]GLOCUENTAS (1)'!$B:$C,2,FALSE) -> IM SOBRG CTA CTE S/F PJ CGEM 1ND
C13: 14011204000102 | D13: 17092.13 | E13: 17092.13 | F13: 17092.13 | G13: =F13-E13 -> 0 | H13: =F13-D13 -> 0 | J13: =VLOOKUP(C13,'[1]GLOCUENTAS (1)'!$B:$C,2,FALSE) -> IM SOBREGIRO CTA CTE PJ S/F CMED 1ND
C14: 14011304000102 | D14: 1130.05 | E14: 1130.05 | F14: 1130.05 | G14: =F14-E14 -> 0 | H14: =F14-D14 -> 0 | J14: =VLOOKUP(C14,'[1]GLOCUENTAS (1)'!$B:$C,2,FALSE) -> IM SOBREGIRO CTA CTE PJ S/F CPEM 1ND
... C19: 14051304000202 | D19: 724017.22 | E19: 724017.22 | F19: 724017.22 | G19: =F19-E19 -> 0 | H19: =F19-D19 -> 0 | J19: =VLOOKUP(C19,'[1]GLOCUENTAS (1)'!$B:$C,2,FALSE) -> IM SOBREG VENC CTA CTE PJ S/F CPEM 1ND
C20: 15071900000922 | D20: 1910011.5 | G20: =F20-E20 -> 0 | H20: =F20-D20 -> -1910011.5 | J20: =VLOOKUP(C20,'[1]GLOCUENTAS (1)'!$B:$C,2,FALSE) -> CTA POR COBRAR IB DIRECTO 1ND
C21: 21010109000101 | D21: 19563006 | E21: 19563006 | F21: 19569477 | G21: =F21-E21 -> 6470.52 | H21: =F21-D21 -> 6470.52 | J21: =VLOOKUP(C21,'[1]GLOCUENTAS (1)'!$B:$C,2,FALSE) -> DEPOSITOS CTA CTE PN 2NC
C22: 21010109000102 | D22: 1.4116187e+09 | E22: 1.4116187e+09 | F22: 1.4116187e+09 | G22: =F22-E22 -> 0 | H22: =F22-D22 -> 0 | J22: =VLOOKUP(C22,'[1]GLOCUENTAS (1)'!$B:$C,2,FALSE) -> DEPOSITOS CTA CTE PJ S/F LUCRO 2NC
C23: 21010109000105 | D23: 6116.6 | E23: 6116.6 | F23: 6116.6 | G23: =F23-E23 -> 0 | H23: =F23-D23 -> 0 | J23: =VLOOKUP(C23,'[1]GLOCUENTAS (1)'!$B:$C,2,FALSE) -> IM C.CTE.AG.DIN.ELEC.PJ C/F 2NC
C24: 21010109000106 | D24: 51351107 | E24: 51351107 | F24: 51351107 | G24: =F24-E24 -> 0 | H24: =F24-D24 -> 0 | J24: =VLOOKUP(C24,'[1]GLOCUENTAS (1)'!$B:$C,2,FALSE) -> CTA CTE BPE PERSONA NATURAL 2NC
C25: 21010109000107 | D25: 1.8884107e+09 | E25: 1.8884107e+09 | F25: 1.8884107e+09 | G25: =F25-E25 -> 0 | H25: =F25-D25 -> 0 | J25: =VLOOKUP(C25,'[1]GLOCUENTAS (1)'!$B:$C,2,FALSE) -> CTA CTE BPE PERSONA JURIDICA 2NC
C26: 21010109000201 | D26: 5.6005808e+09 | E26: 5.6005808e+09 | F26: 5.5913764e+09 | G26: =F26-E26 -> -9204409.8 | H26: =F26-D26 -> -9204409.8 | J26: =VLOOKUP(C26,'[1]GLOCUENTAS (1)'!$B:$C,2,FALSE) -> DEPOSITOS CTA CTE PJ 2NC
C27: 21010200000101 | D27: 893461.33 | E27: 893461.33 | F27: 911246.63 | G27: =F27-E27 -> 17785.3 | H27: =F27-D27 -> 17785.3 | J27: =VLOOKUP(C27,'[1]GLOCUENTAS (1)'!$B:$C,2,FALSE) -> DEPOSITOS CTA CTE PN 2NC
C28: 21010200000103 | D28: 16615046 | E28: 16615046 | F28: 16615446 | G28: =F28-E28 -> 400 | H28: =F28-D28 -> 400 | J28: =VLOOKUP(C28,'[1]GLOCUENTAS (1)'!$B:$C,2,FALSE) -> DEPOSITO CTA CTE PJ S/F LUCRO SIN MOV 2NC
C29: 21010200000201 | D29: 46716534 | E29: 46716534 | F29: 46719053 | G29: =F29-E29 -> 2519.17 | H29: =F29-D29 -> 2519.17 | J29: =VLOOKUP(C29,'[1]GLOCUENTAS (1)'!$B:$C,2,FALSE) -> DEPOSITOS CTA CTE PJ 2NC
C30: 21070201000301 | D30: 48113.71 | E30: 48113.71 | F30: 23857.89 | G30: =F30-E30 -> -24255.82 | H30: =F30-D30 -> -24255.82 | J30: =VLOOKUP(C30,'[1]GLOCUENTAS (1)'!$B:$C,2,FALSE) -> RET.JUD.CTAS.CTES.- PN Y PJ PRIV.S/F LUC2NC
C31: 21070201000303 | D31: 1472.58 | E31: 1472.58 | F31: 1072.58 | G31: =F31-E31 -> -400 | H31: =F31-D31 -> -400 | J31: =VLOOKUP(C31,'[1]GLOCUENTAS (1)'!$B:$C,2,FALSE) -> RET.JUD.CTAS.CTES.- PJ S/F LUCRO 2NC
C32: 21070201000401 | D32: 21590.92 | E32: 21590.92 | F32: 9223481.6 | G32: =F32-E32 -> 9201890.7 | H32: =F32-D32 -> 9201890.7 | J32: =VLOOKUP(C32,'[1]GLOCUENTAS (1)'!$B:$C,2,FALSE) -> RETENC.JUD.CTAS.CTES.- OTRAS PJ 2NC
... C36: 21070902000101 | D36: 1.6674664e+08 | E36: 1.6674664e+08 | F36: 1.6674664e+08 | G36: =F36-E36 -> 0 | H36: =F36-D36 -> 0 | J36: =VLOOKUP(C36,'[1]GLOCUENTAS (1)'!$B:$C,2,FALSE) -> DEPOSITO CTA CTE GARANT INMOBIL OTRAS PJ2NC
C37: 25041900000157 | D37: 6244819.5 | G37: =F37-E37 -> 0 | H37: =F37-D37 -> -6244819.5 | J37: =VLOOKUP(C37,'[1]GLOCUENTAS (1)'!$B:$C,2,FALSE) -> CTA POR PAGAR IB DIRECTO 2NC
C38: 29080900000173 | D38: 17905838 | E38: 17905838 | F38: 17905838 | G38: =F38-E38 -> 0 | H38: =F38-D38 -> 0 | J38: =VLOOKUP(C38,'[1]GLOCUENTAS (1)'!$B:$C,2,FALSE) -> OPERACIONES - CONVENIOS 2NC
C39: 72050103010101 | D39: 13430 | G39: =F39-E39 -> 0 | H39: =F39-D39 -> -13430 | J39: =VLOOKUP(C39,'[1]GLOCUENTAS (1)'!$B:$C,2,FALSE) -> IM LIN.CTA CTE CONSUMO REVOL 7NC
C40: 72050108010151 | D40: 439022000 | G40: =F40-E40 -> 0 | H40: =F40-D40 -> -439022000 | J40: =VLOOKUP(C40,'[1]GLOCUENTAS (1)'!$B:$C,2,FALSE) -> IM LIN NO UTILIZADA CTA CTE REVOL CIVA 7NC
C41: 72050109010151 | D41: 8968200 | G41: =F41-E41 -> 0 | H41: =F41-D41 -> -8968200 | J41: =VLOOKUP(C41,'[1]GLOCUENTAS (1)'!$B:$C,2,FALSE) -> IM LIN NO UTILIZADA CTA CTE REVOL CESF 7NC
C42: 72050110010151 | D42: 2.6382421e+08 | G42: =F42-E42 -> 0 | H42: =F42-D42 -> -2.6382421e+08 | J42: =VLOOKUP(C42,'[1]GLOCUENTAS (1)'!$B:$C,2,FALSE) -> IM LIN NO UTILIZADA CTA CTE REVOL CCOR 7NC
C43: 72050111010151 | D43: 861872.11 | G43: =F43-E43 -> 0 | H43: =F43-D43 -> -861872.11 | J43: =VLOOKUP(C43,'[1]GLOCUENTAS (1)'!$B:$C,2,FALSE) -> IM LIN NO UTILIZADA CTA CTE REVOL CGEM 7NC
C44: 81040200000101 | D44: 0 | G44: =F44-E44 -> 0 | H44: =F44-D44 -> 0 | J44: =VLOOKUP(C44,'[1]GLOCUENTAS (1)'!$B:$C,2,FALSE) -> INT CRED VENC.SUSP-SOBREG PN PJ S/F LUCR7ND
C45: 81040900000213 | D45: 0 | G45: =F45-E45 -> 0 | H45: =F45-D45 -> 0 | J45: =VLOOKUP(C45,'[1]GLOCUENTAS (1)'!$B:$C,2,FALSE) -> MANT SUSPENSO PJ SF IB 7ND
C46: Total | D46: =SUM(D2:D45) -> 1.0127072e+10 | E46: =SUM(E2:E45) -> 9.4062277e+09 | F46: =SUM(F2:F45) -> 9.4062277e+09 | G46: =F46-E46 -> 0 | H46: =F46-D46 -> -7.2084455e+08 | J46: =VLOOKUP(C46,'[1]GLOCUENTAS (1)'!$B:$C,2,FALSE) -> #N/A
A47: $ST | B47: Ahorros Plazo fijo Certificados bancarios Etc | C47: 21010903010113 | F47: 18124.48 | G47: =F47-E47 -> 18124.48 | H47: =F47-D47 -> 18124.48 | J47: =VLOOKUP(C47,'[1]GLOCUENTAS (1)'!$B:$C,2,FALSE) -> CB CAP INT.VCDO PN 2NC
...

Sheet USD
A1: App | B1: Productos | C1: Cuenta contable | D1: Saldo Aplicativo Sin filtros | E1: Saldo Aplicativo con Filtros Agrupaciones aplicados | F1: Saldos Diario 16 Abril Operativo | G1: Cuadre Con Filtros | H1: Cuadre Sin Filtros | I1: Filtros aplicados | J1: Detalle cuenta contable
A2: $IM | B2: Cuentas Corrientes | C2: 72050109010151 | D2: 450000 | G2: =F2-E2 -> 0 | H2: =F2-D2 -> -450000 | J2: IM LIN NO UTILIZADA CTA CTE REVOL CESF 7NC
A3: $IM | C3: 14050304000101 | D3: 3.76 | E3: 3.76 | F3: 3.75 | G3: =F3-E3 -> -0.01 | H3: =F3-D3 -> -0.01 | J3: SOBREGIROS EN CTA CTE PN 1ND
A4: $IM | C4: 29080900000173 | D4: 0 | E4: 0 | F4: 0 | G4: =F4-E4 -> 0 | H4: =F4-D4 -> 0 | J4: OPERACIONES - CONVENIOS 2NC
A5: $IM | C5: 72050103010101 | D5: 10000 | G5: =F5-E5 -> 0 | H5: =F5-D5 -> -10000 | J5: IM LIN.CTA CTE CONSUMO REVOL 7NC
A6: $IM | C6: 72050110010151 | D6: 12000000 | G6: =F6-E6 -> 0 | H6: =F6-D6 -> -12000000 | J6: IM LIN NO UTILIZADA CTA CTE REVOL CCOR 7NC
A7: $IM | C7: 21010109000102 | D7: 37310896 | E7: 37310896 | F7: 37310893 | G7: =F7-E7 -> -2.6 | H7: =F7-D7 -> -2.6 | J7: DEPOSITOS CTA CTE PJ S/F LUCRO 2NC
A8: $IM | C8: 14010704000102 | D8: 0 | E8: 0 | F8: 0 | G8: =F8-E8 -> 0 | H8: =F8-D8 -> 0 | J8: IM SOBREGIRO CTA CTE PJ S/F CESP 1ND
A9: $IM | C9: 14011004000102 | D9: 355.54 | E9: 355.54 | F9: 355.53 | G9: =F9-E9 -> -0.01 | H9: =F9-D9 -> -0.01 | J9: IM SOBREGIRO CTA CTE PJ S/F CCOR 1ND
A10: $IM | C10: 21070902000101 | D10: 11311459 | E10: 11311459 | F10: 11311458 | G10: =F10-E10 -> -1.1 | H10: =F10-D10 -> -1.1 | J10: DEPOSITO CTA CTE GARANT INMOBIL OTRAS PJ2NC
A11: $IM | C11: 81040200000101 | D11: 0 | G11: =F11-E11 -> 0 | H11: =F11-D11 -> 0 | J11: INT CRED VENC.SUSP-SOBREG PN PJ S/F LUCR7ND
A12: $IM | C12: 21010109000101 | D12: 3307859.8 | E12: 3307859.8 | F12: 3307914.5 | G12: =F12-E12 -> 54.78 | H12: =F12-D12 -> 54.78 | J12: DEPOSITOS CTA CTE PN 2NC
A13: $IM | C13: 14011304000102 | D13: 10.1 | E13: 10.1 | F13: 10.08 | G13: =F13-E13 -> -0.02 | H13: =F13-D13 -> -0.02 | J13: IM SOBREGIRO CTA CTE PJ S/F CPEM 1ND
A14: $IM | C14: 21070401010301 | D14: 0.03 | E14: 0.03 | F14: 0.02 | G14: =F14-E14 -> -0.01 | H14: =F14-D14 -> -0.01 | J14: DEPOSITO GTIA CTA CTE-PJ S/F LUCRO 2NC
A15: $IM | C15: 21010109000107 | D15: 3.0352975e+08 | E15: 3.0352975e+08 | F15: 3.0352942e+08 | G15: =F15-E15 -> -326.63 | H15: =F15-D15 -> -326.63 | J15: CTA CTE BPE PERSONA JURIDICA 2NC
A16: $IM | C16: 21010200000101 | D16: 89529.59 | E16: 89529.59 | F16: 87029.33 | G16: =F16-E16 -> -2500.26 | H16: =F16-D16 -> -2500.26 | J16: DEPOSITOS CTA CTE PN 2NC
A17: $IM | C17: 14050204000101 | D17: 10400.87 | E17: 10400.87 | F17: 10400.72 | G17: =F17-E17 -> -0.15 | H17: =F17-D17 -> -0.15 | J17: SOBREGIRO VENC MES SIN FINES 1ND
A18: $IM | C18: 21070401020301 | D18: 2260792.7 | E18: 2260792.7 | F18: 2260791.3 | G18: =F18-E18 -> -1.41 | H18: =F18-D18 -> -1.41 | J18: DEPOSITO GTIA CTA CTE-OTRAS PJ 2NC
A19: $IM | C19: 21010200000103 | D19: 764253.46 | E19: 764253.46 | F19: 764252.21 | G19: =F19-E19 -> -1.25 | H19: =F19-D19 -> -1.25 | J19: DEPOSITO CTA CTE PJ S/F LUCRO SIN MOV 2NC
A20: $IM | C20: 21010109000106 | D20: 5771281.6 | E20: 5771281.6 | F20: 5771273.3 | G20: =F20-E20 -> -8.29 | H20: =F20-D20 -> -8.29 | J20: CTA CTE BPE PERSONA NATURAL 2NC
A21: $IM | C21: 14051104000202 | D21: 43561.89 | E21: 43561.89 | F21: 43561.81 | G21: =F21-E21 -> -0.08 | H21: =F21-D21 -> -0.08 | J21: IM SOBREG VENC CTA CTE PJ S/F CGEM 1ND
A22: $IM | C22: 14011104000102 | D22: 63689.09 | E22: 63689.09 | F22: 63689.04 | G22: =F22-E22 -> -0.05 | H22: =F22-D22 -> -0.05 | J22: IM SOBREGIRO CTA CTE PJ S/F CGEM 1ND
A23: $IM | C23: 14051204000202 | D23: 405845.56 | E23: 405845.56 | F23: 405845.42 | G23: =F23-E23 -> -0.14 | H23: =F23-D23 -> -0.14 | J23: IM SOBREG VENC CTA CTE PJ S/F CMED 1ND
A24: $IM | C24: 72050108010151 | D24: 39000000 | G24: =F24-E24 -> 0 | H24: =F24-D24 -> -39000000 | J24: IM LIN NO UTILIZADA CTA CTE REVOL CIVA 7NC
A25: $IM | C25: 72050111010151 | D25: 25000 | G25: =F25-E25 -> 0 | H25: =F25-D25 -> -25000 | J25: IM LIN NO UTILIZADA CTA CTE REVOL CGEM 7NC
A26: $IM | C26: 14051304000202 | D26: 78851.98 | E26: 78851.98 | F26: 78851.93 | G26: =F26-E26 -> -0.05 | H26: =F26-D26 -> -0.05 | J26: IM SOBREG VENC CTA CTE PJ S/F CPEM 1ND
A27: $IM | C27: 14010204000106 | D27: 230.27 | E27: 230.27 | F27: 230.26 | G27: =F27-E27 -> -0.01 | H27: =F27-D27 -> -0.01 | J27: SOBREGIRO CTAS CTE S/F PJ MES106 1ND
A28: $IM | D28: 1207177.9 | G28: =F28-E28 -> 0 | H28: =F28-D28 -> -1207177.9 | J28: #N/A
A29: $IM | C29: 81040900000213 | D29: 0 | G29: =F29-E29 -> 0 | H29: =F29-D29 -> 0 | J29: MANT SUSPENSO PJ SF IB 7ND
A30: $IM | C30: 21010109000201 | D30: 1.1656272e+09 | E30: 1.1656272e+09 | F30: 1.1656345e+09 | G30: =F30-E30 -> 7318.44 | H30: =F30-D30 -> 7318.44 | J30: DEPOSITOS CTA CTE PJ 2NC
A31: $IM | C31: 14011204000102 | D31: 30095.32 | E31: 30095.32 | F31: 30095.29 | G31: =F31-E31 -> -0.03 | H31: =F31-D31 -> -0.03 | J31: IM SOBREGIRO CTA CTE PJ S/F CMED 1ND
A32: $IM | C32: 21070201000301 | D32: 12511.54 | E32: 12511.54 | F32: 14950.2 | G32: =F32-E32 -> 2438.66 | H32: =F32-D32 -> 2438.66 | J32: RET.JUD.CTAS.CTES.- PN Y PJ PRIV.S/F LUC2NC
A33: $IM | C33: 21070201000401 | D33: 9039.8 | E33: 9039.8 | F33: 905 | G33: =F33-E33 -> -8134.8 | H33: =F33-D33 -> -8134.8 | J33: RETENC.JUD.CTAS.CTES.- OTRAS PJ 2NC
A34: $IM | C34: 21010200000201 | D34: 17596732 | E34: 17596732 | F34: 17597432 | G34: =F34-E34 -> 700.23 | H34: =F34-D34 -> 700.23 | J34: DEPOSITOS CTA CTE PJ 2NC
A35: $IM | C35: TOTALES | D35: =SUM(D2:D34) -> 1.6009165e+09 | E35: =SUM(E2:E34) -> 1.5482243e+09 | F35: =SUM(F2:F34) -> 1.5482238e+09 | G35: =F35-E35 -> -464.79 | H35: =F35-D35 -> -52692643 | J35: #N/A
A36: $ST | B36: Ahorros Plazo fijo Certificados bancarios Etc HAY EUROS, TODAVIA NO ESTÁ DEL TODO CORRECTO ESTOS MONTOS | C36: 21070402010204 | F36: 3044063.5 | G36: =F36-E36 -> 3044063.5 | H36: =F36-D36 -> 3044063.5 | J36: BL-CB GTIA CONTING PJ S/F LUCRO 2NC
A37: $ST | C37: 21070201000101 | D37: 58.98 | E37: 58.98 | F37: 997763.77 | G37: =F37-E37 -> 997704.79 | H37: =F37-D37 -> 997704.79 | J37: BENEFICIOS SOCIALES DE TRABAJADORES 2NC
A38: $ST | C38: 21020101000111 | D38: 1.1737247e+08 | E38: 1.1737247e+08 | F38: 1.1737148e+08 | G38: =F38-E38 -> -993.05 | H38: =F38-D38 -> -993.05 | J38: AHORROS CTA.ALCANCIA VIRTUAL 2NC
A39: $ST | C39: 21030301000108 | F39: 50718.21 | G39: =F39-E39 -> 50718.21 | H39: =F39-D39 -> 50718.21 | J39: DEP PLAZO CAPITAL PJSL 2NC
A40: $ST | C40: 21070401010101 | F40: 4737.63 | G40: =F40-E40 -> 4737.63 | H40: =F40-D40 -> 4737.63 | J40: AHORROS MILLONARIA GTIA CAPITAL PN 2NC
...

Sheet EUR
A1: App | B1: Productos | C1: Cuenta contable | D1: Saldo Aplicativo Sin filtros | E1: Saldo Aplicativo con Filtros Agrupaciones aplicados | F1: Saldos Diario 16 Abril Operativo | G1: Cuadre Con Filtros | H1: Cuadre Sin Filtros | I1: Filtros aplicados | J1: Detalle cuenta contable
A2: $ST | B2: Ahorros Plazo fijo Certificados bancarios Etc HAY EUROS, TODAVIA NO ESTÁ DEL TODO CORRECTO ESTOS MONTOS | C2: 21070201000105 | D2: 9164.74 | E2: 8935.04 | F2: =VLOOKUP(C2,USD!C36:F74,4,0) -> 410617.61 | G2: =F2-E2 -> 401682.57 | H2: =F2-D2 -> 401452.87
A3: $ST | D3: 1.5452258e+08 | E3: 1.3362183e+08 | G3: =F3-E3 -> -1.3362183e+08 | H3: =F3-D3 -> -1.5452258e+08
A4: $ST | C4: TOTALES | D4: =SUM(D2:D3) -> 1.5453175e+08 | E4: =SUM(E2:E3) -> 1.3363076e+08 | F4: =SUM(F2:F3) -> 410617.61 | G4: =F4-E4 -> -1.3322014e+08 | H4: =F4-D4 -> -1.5412113e+08
A5: BKT | B5: "Carta de Crédito de Exportaciones/Importaciones Cobranza de Exportaciones/Importaciones" HAY EUROS, TODAVIA NO ESTÁ DEL TODO CORRECTO ESTOS MONTOS | C5: 71030000000102 | D5: 200000 | E5: 200000 | F5: =VLOOKUP(C5,USD!C76:F93,4,0) -> 94152344 | G5: =F5-E5 -> 93952344 | H5: =F5-D5 -> 93952344
A6: BKT | D6: 294557.13 | E6: 294557.13 | G6: =F6-E6 -> -294557.13 | H6: =F6-D6 -> -294557.13
A7: BKT | C7: TOTALES | D7: =SUM(D5:D6) -> 494557.13 | E7: =SUM(E5:E6) -> 494557.13 | F7: =SUM(F5:F6) -> 94152344 | G7: =F7-E7 -> 93657787 | H7: =F7-D7 -> 93657787

Sheet Consolidado
A1: App | B1: Productos | C1: Moneda | D1: Saldo Aplicativo Sin filtros | E1: Saldo Aplicativo con Filtros Agrupaciones aplicados | F1: Saldos Diario 16 Abril Operativo | G1: Cuadre Con Filtros | H1: Cuadre Sin Filtros
A2: $IM | B2: Cuentas Corrientes | C2: PSS | D2: =PSS!D46 -> 1.0127072e+10 | E2: =PSS!E46 -> 9.4062277e+09 | F2: =PSS!F46 -> 9.4062277e+09 | G2: =F2-E2 -> 0 | H2: =F2-D2 -> -7.2084455e+08
A3: $IM | C3: USD | D3: 1.6009165e+09 | E3: 1.5482243e+09 | F3: 1.5482238e+09 | G3: -464.79 | H3: -52692643
A4: $ST | B4: Ahorros Plazo fijo Certificados bancarios Etc | C4: PSS | D4: =PSS!D87 -> 2.2869629e+10 | E4: =PSS!E87 -> 2.1183806e+10 | F4: =PSS!F87 -> 2.1183806e+10 | G4: =F4-E4 -> 0 | H4: =F4-D4 -> -1.685823e+09
A5: $ST | C5: USD | D5: 3.1340857e+09 | E5: 2.7607016e+09 | F5: 2918049162 | G5: 1.5734757e+08 | H5: -2.1603652e+08
A6: BKT | B6: "Carta de Crédito de Exportaciones/Importaciones Cobranza de Exportaciones/Importaciones" | C6: PSS | D6: =PSS!D89 -> 9359451.6 | E6: =PSS!E89 -> 9359451.6 | F6: =PSS!F89 -> 9359451.6 | G6: =F6-E6 -> 0 | H6: =F6-D6 -> 0
A7: BKT | C7: USD | D7: 2.1925037e+08 | E7: 2.1276786e+08 | F7: 2.1335024e+08 | G7: 582378.68 | H7: -5900129.3
A8: CDO | B8: Tarjetas de Crédito | C8: PSS | D8: =PSS!D142 -> 4.9532964e+09 | E8: =PSS!E142 -> 4.9532964e+09 | F8: =PSS!F142 -> 4.9532964e+09 | G8: =F8-E8 -> 0 | H8: =F8-D8 -> 0
A9: CDO | C9: USD | D9: 1.2416529e+08 | E9: 1.2416529e+08 | F9: 1.2416422e+08 | G9: -1078.06 | H9: -1078.06
A10: CNS | B10: Créditos (consumo, vehicular, etc) | C10: PSS | D10: =PSS!D335 -> 1.7891351e+10 | E10: =PSS!E335 -> 1.5153944e+10 | F10: =PSS!F335 -> 1.6927632e+10 | G10: =F10-E10 -> 1.7736878e+09 | H10: =F10-D10 -> -9.637195e+08
A11: HIP | B11: Créditos Hipotecarios | C11: USD | D11: 1.4627929e+08 | E11: 1.4627387e+08 | F11: 1.4627927e+08 | G11: 5399.07 | H11: 16990805
A12: FCD | B12: Financiamiento y Cobranza de documentos | C12: PSS | D12: =PSS!D361 -> 2.3854596e+09 | E12: =PSS!E361 -> 1.1924076e+09 | F12: =PSS!F361 -> 1.1924076e+09 | G12: =F12-E12 -> 0 | H12: =F12-D12 -> -1.193052e+09
A13: FCD | C13: USD | D13: 8.7455815e+08 | E13: 4.3500722e+08 | F13: 4.3500694e+08 | G13: -277.72 | H13: -4.3955121e+08
A14: FMU | B14: Fondos Mutuos de Inversión | C14: PSS | D14: =PSS!D365 -> 4.4348046e+09 | E14: =PSS!E365 -> 3.9549872e+09 | F14: =PSS!F365 -> 3.9549872e+09 | G14: =F14-E14 -> 0 | H14: =F14-D14 -> -4.7981745e+08
A15: FMU | C15: USD | D15: 2.0664538e+09 | E15: 1.6761203e+09 | F15: 1.6761199e+09 | G15: -488.71 | H15: -2.0664538e+09
A16: JCC | B16: Judicial Condonación o Castigo | C16: PSS | D16: =PSS!D549 -> 3.0951077e+09 | E16: =PSS!E549 -> 2.9625355e+09 | F16: =PSS!F549 -> 2.9625355e+09 | G16: =F16-E16 -> 0 | H16: =F16-D16 -> -1.3257221e+08
A17: JCC | C17: USD | D17: 3.1116577e+08 | E17: 2.6192272e+08 | F17: 2.6192265e+08 | G17: -64.37 | H17: -49243122
A18: LIC | B18: Créditos de consumo por convenio | C18: PSS | D18: =PSS!D570 -> 1.1089622e+10 | E18: =PSS!E570 -> 5.4604585e+09 | F18: =PSS!F570 -> 5.4604585e+09 | G18: =F18-E18 -> 0 | H18: =F18-D18 -> -5.6291632e+09
A19: LID | C19: USD | D19: 0 | E19: 0 | F19: 0 | G19: 0 | H19: 0
A20: LPC | B20: Leasing y pagares en cuotas | C20: PSS | D20: =PSS!D694 -> 8.5870972e+09 | E20: =PSS!E694 -> 8.5395057e+09 | F20: =PSS!F694 -> 8.5395057e+09 | G20: =F20-E20 -> 0 | H20: =F20-D20 -> -47591439
A21: LPC | C21: USD | D21: 3.241257e+09 | E21: 3.1923472e+09 | F21: 3.2219566e+09 | G21: 29609399 | H21: -19300383
A22: MYP | B22: Micro pequeña empresa | C22: PSS | D22: =PSS!D796 -> 1.8062895e+09 | E22: =PSS!E796 -> 1.7663458e+09 | F22: =PSS!F796 -> 1.7663458e+09 | G22: =F22-E22 -> 0 | H22: =F22-D22 -> -39943655
A23: MYP | C23: USD | D23: 1734134.9 | E23: 1683220.3 | F23: 1683220.2 | G23: -0.12 | H23: -1734134.9
A24: PPA | B24: Pago Activos | C24: PSS | D24: 0 | E24: 0 | F24: 0 | G24: =F24-E24 -> 0 | H24: =F24-D24 -> 0
A25: PPA | C25: USD | D25: 0 | E25: 0 | F25: 0 | G25: =F25-E25 -> 0 | H25: =F25-D25 -> 0
A26: PRO | B26: Provisiones | C26: PSS | D26: 0 | E26: 0 | F26: 0 | G26: =F26-E26 -> 0 | H26: =F26-D26 -> 0
A27: PRO | C27: USD | D27: 0 | E27: 0 | F27: 0 | G27: =F27-E27 -> 0 | H27: =F27-D27 -> 0
A28: SCF | B28: Sistema de Carta Fianza | C28: PSS | D28: =PSS!D804 -> 1.9666186e+09 | E28: =PSS!E804 -> 1.9666186e+09 | F28: =PSS!F804 -> 1.9666186e+09 | G28: =F28-E28 -> 0 | H28: =F28-D28 -> 0
A29: SCF | C29: USD | D29: 8.9169592e+08 | E29: 8.9169592e+08 | F29: 8.9169591e+08 | G29: -6.9 | H29: -8.9169592e+08
A30: WBC | B30: Workflow banca comercial | C30: PSS | D30: 0 | E30: 0 | F30: 0 | G30: =F30-E30 -> 0 | H30: =F30-D30 -> 0
A31: WBC | C31: USD | D31: 0 | E31: 0 | F31: 0 | G31: =F31-E31 -> 0 | H31: =F31-D31 -> 0
A32: MDC | B32: Tesorería | C32: PSS | D32: =PSS!D868 -> 3.6975686e+10 | E32: =PSS!E868 -> 7.9344375e+09 | F32: =PSS!F868 -> 2.5144303e+10 | G32: =F32-E32 -> 1.7209865e+10 | H32: =F32-D32 -> -1.1831383e+10
A33: MDC | C33: USD | D33: 9.2420009e+09 | E33: 1.9736654e+09 | F33: 4.3455725e+10 | G33: 4.148206e+10 | H33: 3.4213724e+10
A34: GAC | B34: Garantías y Coberturas | C34: PSS | D34: 0 | E34: 0 | F34: 0 | G34: =F34-E34 -> 0 | H34: =F34-D34 -> 0
A35: GAC | C35: USD | D35: 0 | E35: 0 | F35: 0 | G35: =F35-E35 -> 0 | H35: =F35-D35 -> 0
B37: TOTALES CON TESORERIA | C37: PSS | D37: =SUMIF($C$2:$C$35,"PSS",D2:D35) -> 1.2619139e+11 | E37: =SUMIF($C$2:$C$35,"PSS",E2:E35) -> 8.448393e+10 | F37: =SUMIF($C$2:$C$35,"PSS",F2:F35) -> 1.0346748e+11 | G37: =SUMIF($C$2:$C$35,"PSS",G2:G35) -> 1.8983553e+10 | H37: =SUMIF($C$2:$C$35,"PSS",H2:H35) -> -2.272391e+10
C38: USD | D38: =SUMIF($C$3:$C$36,"USD",D3:D36) -> 2.1853563e+10 | E38: =SUMIF($C$3:$C$36,"USD",E3:E36) -> 1.3224575e+10 | F38: =SUMIF($C$3:$C$36,"USD",F3:F36) -> 5.4894177e+10 | G38: =SUMIF($C$3:$C$36,"USD",G3:G36) -> 4.1669602e+10 | H38: =SUMIF($C$3:$C$36,"USD",H3:H36) -> 3.0488106e+10
B40: TOTALES SIN TESORERIA | C40: PSS | D40: =D37-D32 -> 8.9215707e+10 | E40: =E37-E32 -> 7.6549492e+10 | F40: =F37-F32 -> 7.832318e+10 | G40: =G37-G32 -> 1.7736878e+09 | H40: =H37-H32 -> -1.0892527e+10
C41: USD | D41: =D38-D33 -> 1.2611562e+10 | E41: =E38-E33 -> 1.125091e+10 | F41: =F38-F33 -> 1.1438452e+10 | G41: =G38-G33 -> 1.8754237e+08 | H41: =H38-H33 -> -3.7256181e+09
B43: TOTALES SIN TESORERIA Y CNS/HIP | C43: PSS | D43: =D40-D10 -> 7.1324356e+10 | E43: =E40-E10 -> 6.1395548e+10 | F43: =F40-F10 -> 6.1395548e+10 | G43: =G40-G10 -> -1.9073486e-06 | H43: =H40-H10 -> -9.9288074e+09
...
